Workbook

Sheet Fall vs. Spring
A1: Executive Function - English | K1: Executive Function - Spanish
A2: Module | B2: Label | C2: Type | D2: Fall HTKS Score | E2: Spring HTKS Score | K2: Module | L2: Label | M2: Type | N2: Fall HTKS Score | O2: Spring HTKS Score
A3: ATL5a | B3: Control Impulses 1 | C3: Corr | D3: {=XLOOKUP($A3&$C3, 'Fall ENG'!$A:$A&'Fall ENG'!$C:$C, 'Fall ENG'!$D:$D)} -> 0.4081 | E3: {=XLOOKUP($A3&$C3, 'Spring ENG'!$A:$A&'Spring ENG'!$C:$C, 'Spring ENG'!$D:$D)} -> 0.2998 | K3: ATL5a | L3: Control Impulses 1 | M3: Corr | N3: {=XLOOKUP($K3&$M3, 'Fall SPA'!$A:$A&'Fall SPA'!$C:$C, 'Fall SPA'!$D:$D)} -> 0.2287 | O3: {=XLOOKUP($K3&$M3, 'Spring SPA'!$A:$A&'Spring SPA'!$C:$C, 'Spring SPA'!$D:$D)} -> 0.4298
A4: ATL5a | B4: Control Impulses 1 | C4: Prob | D4: {=XLOOKUP($A4&$C4, 'Fall ENG'!$A:$A&'Fall ENG'!$C:$C, 'Fall ENG'!$D:$D)} -> 0 | E4: {=XLOOKUP($A4&$C4, 'Spring ENG'!$A:$A&'Spring ENG'!$C:$C, 'Spring ENG'!$D:$D)} -> 0.0035 | K4: ATL5a | L4: Control Impulses 1 | M4: Prob | N4: {=XLOOKUP($K4&$M4, 'Fall SPA'!$A:$A&'Fall SPA'!$C:$C, 'Fall SPA'!$D:$D)} -> 0.2005 | O4: {=XLOOKUP($K4&$M4, 'Spring SPA'!$A:$A&'Spring SPA'!$C:$C, 'Spring SPA'!$D:$D)} -> 0.0966
A5: ATL5a | B5: Control Impulses 1 | C5: N | D5: {=XLOOKUP($A5&$C5, 'Fall ENG'!$A:$A&'Fall ENG'!$C:$C, 'Fall ENG'!$D:$D)} -> 126 | E5: {=XLOOKUP($A5&$C5, 'Spring ENG'!$A:$A&'Spring ENG'!$C:$C, 'Spring ENG'!$D:$D)} -> 93 | K5: ATL5a | L5: Control Impulses 1 | M5: N | N5: {=XLOOKUP($K5&$M5, 'Fall SPA'!$A:$A&'Fall SPA'!$C:$C, 'Fall SPA'!$D:$D)} -> 33 | O5: {=XLOOKUP($K5&$M5, 'Spring SPA'!$A:$A&'Spring SPA'!$C:$C, 'Spring SPA'!$D:$D)} -> 16
A6: ATL5b | B6: Control Impulses 2 | C6: Corr | D6: {=XLOOKUP($A6&$C6, 'Fall ENG'!$A:$A&'Fall ENG'!$C:$C, 'Fall ENG'!$D:$D)} -> 0.3248 | E6: {=XLOOKUP($A6&$C6, 'Spring ENG'!$A:$A&'Spring ENG'!$C:$C, 'Spring ENG'!$D:$D)} -> 0.1355 | K6: ATL5b | L6: Control Impulses 2 | M6: Corr | N6: {=XLOOKUP($K6&$M6, 'Fall SPA'!$A:$A&'Fall SPA'!$C:$C, 'Fall SPA'!$D:$D)} -> 0.1587 | O6: {=XLOOKUP($K6&$M6, 'Spring SPA'!$A:$A&'Spring SPA'!$C:$C, 'Spring SPA'!$D:$D)} -> 0.4145
A7: ATL5b | B7: Control Impulses 2 | C7: Prob | D7: {=XLOOKUP($A7&$C7, 'Fall ENG'!$A:$A&'Fall ENG'!$C:$C, 'Fall ENG'!$D:$D)} -> 0.0016 | E7: {=XLOOKUP($A7&$C7, 'Spring ENG'!$A:$A&'Spring ENG'!$C:$C, 'Spring ENG'!$D:$D)} -> 0.132 | K7: ATL5b | L7: Control Impulses 2 | M7: Prob | N7: {=XLOOKUP($K7&$M7, 'Fall SPA'!$A:$A&'Fall SPA'!$C:$C, 'Fall SPA'!$D:$D)} -> 0.4487 | O7: {=XLOOKUP($K7&$M7, 'Spring SPA'!$A:$A&'Spring SPA'!$C:$C, 'Spring SPA'!$D:$D)} -> 0.0228
A8: ATL5b | B8: Control Impulses 2 | C8: N | D8: {=XLOOKUP($A8&$C8, 'Fall ENG'!$A:$A&'Fall ENG'!$C:$C, 'Fall ENG'!$D:$D)} -> 92 | E8: {=XLOOKUP($A8&$C8, 'Spring ENG'!$A:$A&'Spring ENG'!$C:$C, 'Spring ENG'!$D:$D)} -> 125 | K8: ATL5b | L8: Control Impulses 2 | M8: N | N8: {=XLOOKUP($K8&$M8, 'Fall SPA'!$A:$A&'Fall SPA'!$C:$C, 'Fall SPA'!$D:$D)} -> 25 | O8: {=XLOOKUP($K8&$M8, 'Spring SPA'!$A:$A&'Spring SPA'!$C:$C, 'Spring SPA'!$D:$D)} -> 30
A9: ATL8 | B9: Working Memory 1 | C9: Corr | D9: {=XLOOKUP($A9&$C9, 'Fall ENG'!$A:$A&'Fall ENG'!$C:$C, 'Fall ENG'!$D:$D)} -> 0.3004 | E9: {=XLOOKUP($A9&$C9, 'Spring ENG'!$A:$A&'Spring ENG'!$C:$C, 'Spring ENG'!$D:$D)} -> 0.229 | K9: ATL8 | L9: Working Memory 1 | M9: Corr | N9: {=XLOOKUP($K9&$M9, 'Fall SPA'!$A:$A&'Fall SPA'!$C:$C, 'Fall SPA'!$D:$D)} -> 0.2025 | O9: {=XLOOKUP($K9&$M9, 'Spring SPA'!$A:$A&'Spring SPA'!$C:$C, 'Spring SPA'!$D:$D)} -> 0.4921
A10: ATL8 | B10: Working Memory 1 | C10: Prob | D10: {=XLOOKUP($A10&$C10, 'Fall ENG'!$A:$A&'Fall ENG'!$C:$C, 'Fall ENG'!$D:$D)} -> 0.0088 | E10: {=XLOOKUP($A10&$C10, 'Spring ENG'!$A:$A&'Spring ENG'!$C:$C, 'Spring ENG'!$D:$D)} -> 0.0329 | K10: ATL8 | L10: Working Memory 1 | M10: Prob | N10: {=XLOOKUP($K10&$M10, 'Fall SPA'!$A:$A&'Fall SPA'!$C:$C, 'Fall SPA'!$D:$D)} -> 0.4058 | O10: {=XLOOKUP($K10&$M10, 'Spring SPA'!$A:$A&'Spring SPA'!$C:$C, 'Spring SPA'!$D:$D)} -> 0.0078
A11: ATL8 | B11: Working Memory 1 | C11: N | D11: {=XLOOKUP($A11&$C11, 'Fall ENG'!$A:$A&'Fall ENG'!$C:$C, 'Fall ENG'!$D:$D)} -> 75 | E11: {=XLOOKUP($A11&$C11, 'Spring ENG'!$A:$A&'Spring ENG'!$C:$C, 'Spring ENG'!$D:$D)} -> 87 | K11: ATL8 | L11: Working Memory 1 | M11: N | N11: {=XLOOKUP($K11&$M11, 'Fall SPA'!$A:$A&'Fall SPA'!$C:$C, 'Fall SPA'!$D:$D)} -> 19 | O11: {=XLOOKUP($K11&$M11, 'Spring SPA'!$A:$A&'Spring SPA'!$C:$C, 'Spring SPA'!$D:$D)} -> 28
A12: ATL9 | B12: Flexible Thinking | C12: Corr | D12: {=XLOOKUP($A12&$C12, 'Fall ENG'!$A:$A&'Fall ENG'!$C:$C, 'Fall ENG'!$D:$D)} -> 0.1825 | E12: {=XLOOKUP($A12&$C12, 'Spring ENG'!$A:$A&'Spring ENG'!$C:$C, 'Spring ENG'!$D:$D)} -> 0.2911 | K12: ATL9 | L12: Flexible Thinking | M12: Corr | N12: {=XLOOKUP($K12&$M12, 'Fall SPA'!$A:$A&'Fall SPA'!$C:$C, 'Fall SPA'!$D:$D)} -> 0.196 | O12: {=XLOOKUP($K12&$M12, 'Spring SPA'!$A:$A&'Spring SPA'!$C:$C, 'Spring SPA'!$D:$D)} -> 0.2771
A13: ATL9 | B13: Flexible Thinking | C13: Prob | D13: {=XLOOKUP($A13&$C13, 'Fall ENG'!$A:$A&'Fall ENG'!$C:$C, 'Fall ENG'!$D:$D)} -> 0.0499 | E13: {=XLOOKUP($A13&$C13, 'Spring ENG'!$A:$A&'Spring ENG'!$C:$C, 'Spring ENG'!$D:$D)} -> 0.0027 | K13: ATL9 | L13: Flexible Thinking | M13: Prob | N13: {=XLOOKUP($K13&$M13, 'Fall SPA'!$A:$A&'Fall SPA'!$C:$C, 'Fall SPA'!$D:$D)} -> 0.2824 | O13: {=XLOOKUP($K13&$M13, 'Spring SPA'!$A:$A&'Spring SPA'!$C:$C, 'Spring SPA'!$D:$D)} -> 0.1457
A14: ATL9 | B14: Flexible Thinking | C14: N | D14: {=XLOOKUP($A14&$C14, 'Fall ENG'!$A:$A&'Fall ENG'!$C:$C, 'Fall ENG'!$D:$D)} -> 116 | E14: {=XLOOKUP($A14&$C14, 'Spring ENG'!$A:$A&'Spring ENG'!$C:$C, 'Spring ENG'!$D:$D)} -> 104 | K14: ATL9 | L14: Flexible Thinking | M14: N | N14: {=XLOOKUP($K14&$M14, 'Fall SPA'!$A:$A&'Fall SPA'!$C:$C, 'Fall SPA'!$D:$D)} -> 32 | O14: {=XLOOKUP($K14&$M14, 'Spring SPA'!$A:$A&'Spring SPA'!$C:$C, 'Spring SPA'!$D:$D)} -> 29
A16: Language - English | K16: Language - Spanish
A17: Module | B17: Label | C17: Type | D17: Fall IGDIS: Picture Naming | E17: Fall IGDIS: What Doesn't Belong | F17: Spring IGDIS: Picture Naming | G17: Spring IGDIS: What Doesn't Belong | K17: Module | L17: Label | M17: Type | N17: Fall IGDIS: Dibujos | O17: Fall IGDIS: Verbos Expresivos | P17: Spring IGDIS: Dibujos | Q17: Spring IGDIS: Verbos Expresivos
A18: LAN6 | B18: Vocabulary | C18: Corr | D18: {=XLOOKUP($A18&$C18, 'Fall ENG'!$A:$A&'Fall ENG'!$C:$C, 'Fall ENG'!$E:$F)} -> 0.1097 | E18: 0.2083 | F18: {=XLOOKUP($A18&$C18, 'Spring ENG'!$A:$A&'Spring ENG'!$C:$C, 'Spring ENG'!$E:$F)} -> 0.2743 | G18: 0.1949 | K18: LAN6 | L18: Vocabulary | M18: Corr | N18: {=XLOOKUP($A18&$C18, 'Fall SPA'!$A:$A&'Fall SPA'!$C:$C, 'Fall SPA'!$E:$F)} -> -0.0631 | O18: 0.3415 | P18: {=XLOOKUP($A18&$C18, 'Spring SPA'!$A:$A&'Spring SPA'!$C:$C, 'Spring SPA'!$E:$F)} -> 0.4056 | Q18: 0.1824
A19: LAN6 | B19: Vocabulary | C19: Prob | D19: {=XLOOKUP($A19&$C19, 'Fall ENG'!$A:$A&'Fall ENG'!$C:$C, 'Fall ENG'!$E:$F)} -> 0.2951 | E19: 0.0709 | F19: {=XLOOKUP($A19&$C19, 'Spring ENG'!$A:$A&'Spring ENG'!$C:$C, 'Spring ENG'!$E:$F)} -> 0.0093 | G19: 0.0656 | K19: LAN6 | L19: Vocabulary | M19: Prob | N19: {=XLOOKUP($A19&$C19, 'Fall SPA'!$A:$A&'Fall SPA'!$C:$C, 'Fall SPA'!$E:$F)} -> 0.7857 | O19: 0.1524 | P19: {=XLOOKUP($A19&$C19, 'Spring SPA'!$A:$A&'Spring SPA'!$C:$C, 'Spring SPA'!$E:$F)} -> 0.0291 | Q19: 0.3625
A20: LAN6 | B20: Vocabulary | C20: N | D20: {=XLOOKUP($A20&$C20, 'Fall ENG'!$A:$A&'Fall ENG'!$C:$C, 'Fall ENG'!$E:$F)} -> 93 | E20: 76 | F20: {=XLOOKUP($A20&$C20, 'Spring ENG'!$A:$A&'Spring ENG'!$C:$C, 'Spring ENG'!$E:$F)} -> 89 | G20: 90 | K20: LAN6 | L20: Vocabulary | M20: N | N20: {=XLOOKUP($A20&$C20, 'Fall SPA'!$A:$A&'Fall SPA'!$C:$C, 'Fall SPA'!$E:$F)} -> 21 | O20: 19 | P20: {=XLOOKUP($A20&$C20, 'Spring SPA'!$A:$A&'Spring SPA'!$C:$C, 'Spring SPA'!$E:$F)} -> 29 | Q20: 27
A21: LAN7a | B21: Word Categories | C21: Corr | D21: {=XLOOKUP($A21&$C21, 'Fall ENG'!$A:$A&'Fall ENG'!$C:$C, 'Fall ENG'!$E:$F)} -> 0.2754 | E21: 0.4871 | F21: {=XLOOKUP($A21&$C21, 'Spring ENG'!$A:$A&'Spring ENG'!$C:$C, 'Spring ENG'!$E:$F)} -> 0.4512 | G21: 0.552 | K21: LAN7a | L21: Word Categories | M21: Corr | N21: {=XLOOKUP($A21&$C21, 'Fall SPA'!$A:$A&'Fall SPA'!$C:$C, 'Fall SPA'!$E:$F)} -> 0.3551 | O21: 0.286 | P21: {=XLOOKUP($A21&$C21, 'Spring SPA'!$A:$A&'Spring SPA'!$C:$C, 'Spring SPA'!$E:$F)} -> 0.4845 | Q21: 0.3253
A22: LAN7a | B22: Word Categories | C22: Prob | D22: {=XLOOKUP($A22&$C22, 'Fall ENG'!$A:$A&'Fall ENG'!$C:$C, 'Fall ENG'!$E:$F)} -> 0.0034 | E22: 0 | F22: {=XLOOKUP($A22&$C22, 'Spring ENG'!$A:$A&'Spring ENG'!$C:$C, 'Spring ENG'!$E:$F)} -> 0 | G22: 0 | K22: LAN7a | L22: Word Categories | M22: Prob | N22: {=XLOOKUP($A22&$C22, 'Fall SPA'!$A:$A&'Fall SPA'!$C:$C, 'Fall SPA'!$E:$F)} -> 0.0426 | O22: 0.1188 | P22: {=XLOOKUP($A22&$C22, 'Spring SPA'!$A:$A&'Spring SPA'!$C:$C, 'Spring SPA'!$E:$F)} -> 0.0067 | Q22: 0.0912
A23: LAN7a | B23: Word Categories | C23: N | D23: {=XLOOKUP($A23&$C23, 'Fall ENG'!$A:$A&'Fall ENG'!$C:$C, 'Fall ENG'!$E:$F)} -> 111 | E23: 95 | F23: {=XLOOKUP($A23&$C23, 'Spring ENG'!$A:$A&'Spring ENG'!$C:$C, 'Spring ENG'!$E:$F)} -> 102 | G23: 102 | K23: LAN7a | L23: Word Categories | M23: N | N23: {=XLOOKUP($A23&$C23, 'Fall SPA'!$A:$A&'Fall SPA'!$C:$C, 'Fall SPA'!$E:$F)} -> 33 | O23: 31 | P23: {=XLOOKUP($A23&$C23, 'Spring SPA'!$A:$A&'Spring SPA'!$C:$C, 'Spring SPA'!$E:$F)} -> 30 | Q23: 28
A24: LAN7b | B24: Shared Characteristics | C24: Corr | D24: {=XLOOKUP($A24&$C24, 'Fall ENG'!$A:$A&'Fall ENG'!$C:$C, 'Fall ENG'!$E:$F)} -> 0.3467 | E24: 0.3026 | F24: {=XLOOKUP($A24&$C24, 'Spring ENG'!$A:$A&'Spring ENG'!$C:$C, 'Spring ENG'!$E:$F)} -> 0.1467 | G24: 0.2283 | K24: LAN7b | L24: Shared Characteristics | M24: Corr | N24: {=XLOOKUP($A24&$C24, 'Fall SPA'!$A:$A&'Fall SPA'!$C:$C, 'Fall SPA'!$E:$F)} -> 0.3792 | O24: 0.236 | P24: {=XLOOKUP($A24&$C24, 'Spring SPA'!$A:$A&'Spring SPA'!$C:$C, 'Spring SPA'!$E:$F)} -> 0.3356 | Q24: 0.2801
A25: LAN7b | B25: Shared Characteristics | C25: Prob | D25: {=XLOOKUP($A25&$C25, 'Fall ENG'!$A:$A&'Fall ENG'!$C:$C, 'Fall ENG'!$E:$F)} -> 0.0001 | E25: 0.002 | F25: {=XLOOKUP($A25&$C25, 'Spring ENG'!$A:$A&'Spring ENG'!$C:$C, 'Spring ENG'!$E:$F)} -> 0.1297 | G25: 0.0175 | K25: LAN7b | L25: Shared Characteristics | M25: Prob | N25: {=XLOOKUP($A25&$C25, 'Fall SPA'!$A:$A&'Fall SPA'!$C:$C, 'Fall SPA'!$E:$F)} -> 0.0354 | O25: 0.2178 | P25: {=XLOOKUP($A25&$C25, 'Spring SPA'!$A:$A&'Spring SPA'!$C:$C, 'Spring SPA'!$E:$F)} -> 0.0698 | Q25: 0.1488
A26: LAN7b | B26: Shared Characteristics | C26: N | D26: {=XLOOKUP($A26&$C26, 'Fall ENG'!$A:$A&'Fall ENG'!$C:$C, 'Fall ENG'!$E:$F)} -> 116 | E26: 102 | F26: {=XLOOKUP($A26&$C26, 'Spring ENG'!$A:$A&'Spring ENG'!$C:$C, 'Spring ENG'!$E:$F)} -> 108 | G26: 108 | K26: LAN7b | L26: Shared Characteristics | M26: N | N26: {=XLOOKUP($A26&$C26, 'Fall SPA'!$A:$A&'Fall SPA'!$C:$C, 'Fall SPA'!$E:$F)} -> 31 | O26: 29 | P26: {=XLOOKUP($A26&$C26, 'Spring SPA'!$A:$A&'Spring SPA'!$C:$C, 'Spring SPA'!$E:$F)} -> 30 | Q26: 28
A28: Literacy - English
A29: Module | B29: Label | C29: Type | D29: Fall TOPEL Score | E29: Spring TOPEL Score
A30: LIT1a | B30: Rhyme | C30: Corr | D30: {=XLOOKUP($A30&$C30, 'Fall ENG'!$A:$A&'Fall ENG'!$C:$C, 'Fall ENG'!$G:$G)} -> 0.0577 | E30: {=XLOOKUP($A30&$C30, 'Spring ENG'!$A:$A&'Spring ENG'!$C:$C, 'Spring ENG'!$G:$G)} -> 0.4687
A31: LIT1a | B31: Rhyme | C31: Prob | D31: {=XLOOKUP($A31&$C31, 'Fall ENG'!$A:$A&'Fall ENG'!$C:$C, 'Fall ENG'!$G:$G)} -> 0.5193 | E31: {=XLOOKUP($A31&$C31, 'Spring ENG'!$A:$A&'Spring ENG'!$C:$C, 'Spring ENG'!$G:$G)} -> 0.0009
A32: LIT1a | B32: Rhyme | C32: N | D32: {=XLOOKUP($A32&$C32, 'Fall ENG'!$A:$A&'Fall ENG'!$C:$C, 'Fall ENG'!$G:$G)} -> 127 | E32: {=XLOOKUP($A32&$C32, 'Spring ENG'!$A:$A&'Spring ENG'!$C:$C, 'Spring ENG'!$G:$G)} -> 47
A33: LIT1b | B33: Blending & Adding | C33: Corr | D33: {=XLOOKUP($A33&$C33, 'Fall ENG'!$A:$A&'Fall ENG'!$C:$C, 'Fall ENG'!$G:$G)} -> 0.1873 | E33: {=XLOOKUP($A33&$C33, 'Spring ENG'!$A:$A&'Spring ENG'!$C:$C, 'Spring ENG'!$G:$G)} -> 0.4019
A34: LIT1b | B34: Blending & Adding | C34: Prob | D34: {=XLOOKUP($A34&$C34, 'Fall ENG'!$A:$A&'Fall ENG'!$C:$C, 'Fall ENG'!$G:$G)} -> 0.0365 | E34: {=XLOOKUP($A34&$C34, 'Spring ENG'!$A:$A&'Spring ENG'!$C:$C, 'Spring ENG'!$G:$G)} -> 0
A35: LIT1b | B35: Blending & Adding | C35: N | D35: {=XLOOKUP($A35&$C35, 'Fall ENG'!$A:$A&'Fall ENG'!$C:$C, 'Fall ENG'!$G:$G)} -> 125 | E35: {=XLOOKUP($A35&$C35, 'Spring ENG'!$A:$A&'Spring ENG'!$C:$C, 'Spring ENG'!$G:$G)} -> 123
A36: LIT1c | B36: Segmenting | C36: Corr | D36: {=XLOOKUP($A36&$C36, 'Fall ENG'!$A:$A&'Fall ENG'!$C:$C, 'Fall ENG'!$G:$G)} -> 0.3209 | E36: {=XLOOKUP($A36&$C36, 'Spring ENG'!$A:$A&'Spring ENG'!$C:$C, 'Spring ENG'!$G:$G)} -> 0.3551
A37: LIT1c | B37: Segmenting | C37: Prob | D37: {=XLOOKUP($A37&$C37, 'Fall ENG'!$A:$A&'Fall ENG'!$C:$C, 'Fall ENG'!$G:$G)} -> 0.0004 | E37: {=XLOOKUP($A37&$C37, 'Spring ENG'!$A:$A&'Spring ENG'!$C:$C, 'Spring ENG'!$G:$G)} -> 0.0691
A38: LIT1c | B38: Segmenting | C38: N | D38: {=XLOOKUP($A38&$C38, 'Fall ENG'!$A:$A&'Fall ENG'!$C:$C, 'Fall ENG'!$G:$G)} -> 119 | E38: {=XLOOKUP($A38&$C38, 'Spring ENG'!$A:$A&'Spring ENG'!$C:$C, 'Spring ENG'!$G:$G)} -> 27
A39: LIT1d | B39: Decoding & Encoding | C39: Corr | D39: {=XLOOKUP($A39&$C39, 'Fall ENG'!$A:$A&'Fall ENG'!$C:$C, 'Fall ENG'!$G:$G)} -> 0.041 | E39: {=XLOOKUP($A39&$C39, 'Spring ENG'!$A:$A&'Spring ENG'!$C:$C, 'Spring ENG'!$G:$G)} -> 0.4116
A40: LIT1d | B40: Decoding & Encoding | C40: Prob | D40: {=XLOOKUP($A40&$C40, 'Fall ENG'!$A:$A&'Fall ENG'!$C:$C, 'Fall ENG'!$G:$G)} -> 0.7797 | E40: {=XLOOKUP($A40&$C40, 'Spring ENG'!$A:$A&'Spring ENG'!$C:$C, 'Spring ENG'!$G:$G)} -> 0.0015
A41: LIT1d | B41: Decoding & Encoding | C41: N | D41: {=XLOOKUP($A41&$C41, 'Fall ENG'!$A:$A&'Fall ENG'!$C:$C, 'Fall ENG'!$G:$G)} -> 49 | E41: {=XLOOKUP($A41&$C41, 'Spring ENG'!$A:$A&'Spring ENG'!$C:$C, 'Spring ENG'!$G:$G)} -> 57
... A59: LIT5 | B59: Answer Questions | C59: N | D59: {=XLOOKUP($A59&$C59, 'Fall ENG'!$A:$A&'Fall ENG'!$C:$C, 'Fall ENG'!$G:$G)} -> 36 | E59: {=XLOOKUP($A59&$C59, 'Spring ENG'!$A:$A&'Spring ENG'!$C:$C, 'Spring ENG'!$G:$G)} -> 64
...

Sheet Spring ENG
A1: Variable | B1: Label | C1: Type | D1: htks_score | E1: igdis_Picture_Naming_score | F1: igdis_Which_One_Doesn't_Belong_score | G1: topel_pa_stdscore | H1: rema_a_irt | I1: rema_b_irt | J1: rema_tot_irt | K1: Strongest correlation | L1: Expected strongest | M1: Match?
A2: ATL5a | B2: Control Impulses 1 | C2: Corr | D2: 0.2998 | E2: 0.151 | F2: 0.2917 | G2: 0.1727 | H2: 0.3427 | I2: 0.4487 | J2: 0.4885 | K2: {=IF(C2="Corr", INDEX($D$1:$J$1, XMATCH(MAX(D2:J2), D2:J2)), "")} -> rema_tot_irt | L2: =IF(AND(LEFT(A2,3)="ATL",C2="Corr"),"htks", IF(AND(LEFT(A2,3)="LAN",C2="Corr"),"igdis", IF(AND(LEFT(A2,3)="LIT",C2="Corr"),"topel", IF(AND(LEFT(A2,3)="MAT",C2="Corr"),"rema","")))) -> htks | M2: =IF(AND(LEFT(K2, 4) = LEFT(L2, 4), C2 = "Corr"), 1, "")
A3: ATL5a | B3: Control Impulses 1 | C3: Prob | D3: 0.0035 | E3: 0.1531 | F3: 0.0053 | G3: 0.0979 | H3: 0.0008 | I3: 0 | J3: 0 | K3: {=IF(C3="Corr", INDEX($D$1:$J$1, XMATCH(MAX(D3:J3), D3:J3)), "")} | L3: =IF(AND(LEFT(A3,3)="ATL",C3="Corr"),"htks", IF(AND(LEFT(A3,3)="LAN",C3="Corr"),"igdis", IF(AND(LEFT(A3,3)="LIT",C3="Corr"),"topel", IF(AND(LEFT(A3,3)="MAT",C3="Corr"),"rema","")))) | M3: =IF(AND(LEFT(K3, 4) = LEFT(L3, 4), C3 = "Corr"), 1, "")
A4: ATL5a | B4: Control Impulses 1 | C4: N | D4: 93 | E4: 91 | F4: 90 | G4: 93 | H4: 92 | I4: 93 | J4: 92 | K4: {=IF(C4="Corr", INDEX($D$1:$J$1, XMATCH(MAX(D4:J4), D4:J4)), "")} | L4: =IF(AND(LEFT(A4,3)="ATL",C4="Corr"),"htks", IF(AND(LEFT(A4,3)="LAN",C4="Corr"),"igdis", IF(AND(LEFT(A4,3)="LIT",C4="Corr"),"topel", IF(AND(LEFT(A4,3)="MAT",C4="Corr"),"rema","")))) | M4: =IF(AND(LEFT(K4, 4) = LEFT(L4, 4), C4 = "Corr"), 1, "")
A5: ATL5b | B5: Control Impulses 2 | C5: Corr | D5: 0.1355 | E5: 0.2629 | F5: 0.3169 | G5: 0.1199 | H5: 0.3399 | I5: 0.3221 | J5: 0.3746 | K5: {=IF(C5="Corr", INDEX($D$1:$J$1, XMATCH(MAX(D5:J5), D5:J5)), "")} -> rema_tot_irt | L5: =IF(AND(LEFT(A5,3)="ATL",C5="Corr"),"htks", IF(AND(LEFT(A5,3)="LAN",C5="Corr"),"igdis", IF(AND(LEFT(A5,3)="LIT",C5="Corr"),"topel", IF(AND(LEFT(A5,3)="MAT",C5="Corr"),"rema","")))) -> htks | M5: =IF(AND(LEFT(K5, 4) = LEFT(L5, 4), C5 = "Corr"), 1, "")
A6: ATL5b | B6: Control Impulses 2 | C6: Prob | D6: 0.132 | E6: 0.0039 | F6: 0.0005 | G6: 0.1813 | H6: 0.0001 | I6: 0.0002 | J6: 0 | K6: {=IF(C6="Corr", INDEX($D$1:$J$1, XMATCH(MAX(D6:J6), D6:J6)), "")} | L6: =IF(AND(LEFT(A6,3)="ATL",C6="Corr"),"htks", IF(AND(LEFT(A6,3)="LAN",C6="Corr"),"igdis", IF(AND(LEFT(A6,3)="LIT",C6="Corr"),"topel", IF(AND(LEFT(A6,3)="MAT",C6="Corr"),"rema","")))) | M6: =IF(AND(LEFT(K6, 4) = LEFT(L6, 4), C6 = "Corr"), 1, "")
A7: ATL5b | B7: Control Impulses 2 | C7: N | D7: 125 | E7: 119 | F7: 118 | G7: 126 | H7: 125 | I7: 126 | J7: 125 | K7: {=IF(C7="Corr", INDEX($D$1:$J$1, XMATCH(MAX(D7:J7), D7:J7)), "")} | L7: =IF(AND(LEFT(A7,3)="ATL",C7="Corr"),"htks", IF(AND(LEFT(A7,3)="LAN",C7="Corr"),"igdis", IF(AND(LEFT(A7,3)="LIT",C7="Corr"),"topel", IF(AND(LEFT(A7,3)="MAT",C7="Corr"),"rema","")))) | M7: =IF(AND(LEFT(K7, 4) = LEFT(L7, 4), C7 = "Corr"), 1, "")
A8: ATL8 | B8: Working Memory 1 | C8: Corr | D8: 0.229 | E8: 0.2457 | F8: 0.4253 | G8: 0.3095 | H8: 0.4161 | I8: 0.3453 | J8: 0.4286 | K8: {=IF(C8="Corr", INDEX($D$1:$J$1, XMATCH(MAX(D8:J8), D8:J8)), "")} -> rema_tot_irt | L8: =IF(AND(LEFT(A8,3)="ATL",C8="Corr"),"htks", IF(AND(LEFT(A8,3)="LAN",C8="Corr"),"igdis", IF(AND(LEFT(A8,3)="LIT",C8="Corr"),"topel", IF(AND(LEFT(A8,3)="MAT",C8="Corr"),"rema","")))) -> htks | M8: =IF(AND(LEFT(K8, 4) = LEFT(L8, 4), C8 = "Corr"), 1, "")
A9: ATL8 | B9: Working Memory 1 | C9: Prob | D9: 0.0329 | E9: 0.0243 | F9: 0.0001 | G9: 0.0035 | H9: 0.0001 | I9: 0.0011 | J9: 0 | K9: {=IF(C9="Corr", INDEX($D$1:$J$1, XMATCH(MAX(D9:J9), D9:J9)), "")} | L9: =IF(AND(LEFT(A9,3)="ATL",C9="Corr"),"htks", IF(AND(LEFT(A9,3)="LAN",C9="Corr"),"igdis", IF(AND(LEFT(A9,3)="LIT",C9="Corr"),"topel", IF(AND(LEFT(A9,3)="MAT",C9="Corr"),"rema","")))) | M9: =IF(AND(LEFT(K9, 4) = LEFT(L9, 4), C9 = "Corr"), 1, "")
A10: ATL8 | B10: Working Memory 1 | C10: N | D10: 87 | E10: 84 | F10: 84 | G10: 87 | H10: 86 | I10: 87 | J10: 86 | K10: {=IF(C10="Corr", INDEX($D$1:$J$1, XMATCH(MAX(D10:J10), D10:J10)), "")} | L10: =IF(AND(LEFT(A10,3)="ATL",C10="Corr"),"htks", IF(AND(LEFT(A10,3)="LAN",C10="Corr"),"igdis", IF(AND(LEFT(A10,3)="LIT",C10="Corr"),"topel", IF(AND(LEFT(A10,3)="MAT",C10="Corr"),"rema","")))) | M10: =IF(AND(LEFT(K10, 4) = LEFT(L10, 4), C10 = "Corr"), 1, "")
A11: ATL9 | B11: Flexible Thinking | C11: Corr | D11: 0.2911 | E11: 0.2234 | F11: 0.3089 | G11: 0.3133 | H11: 0.2687 | I11: 0.3355 | J11: 0.3528 | K11: {=IF(C11="Corr", INDEX($D$1:$J$1, XMATCH(MAX(D11:J11), D11:J11)), "")} -> rema_tot_irt | L11: =IF(AND(LEFT(A11,3)="ATL",C11="Corr"),"htks", IF(AND(LEFT(A11,3)="LAN",C11="Corr"),"igdis", IF(AND(LEFT(A11,3)="LIT",C11="Corr"),"topel", IF(AND(LEFT(A11,3)="MAT",C11="Corr"),"rema","")))) -> htks | M11: =IF(AND(LEFT(K11, 4) = LEFT(L11, 4), C11 = "Corr"), 1, "")
A12: ATL9 | B12: Flexible Thinking | C12: Prob | D12: 0.0027 | E12: 0.0262 | F12: 0.0017 | G12: 0.0011 | H12: 0.0058 | I12: 0.0005 | J12: 0.0002 | K12: {=IF(C12="Corr", INDEX($D$1:$J$1, XMATCH(MAX(D12:J12), D12:J12)), "")} | L12: =IF(AND(LEFT(A12,3)="ATL",C12="Corr"),"htks", IF(AND(LEFT(A12,3)="LAN",C12="Corr"),"igdis", IF(AND(LEFT(A12,3)="LIT",C12="Corr"),"topel", IF(AND(LEFT(A12,3)="MAT",C12="Corr"),"rema","")))) | M12: =IF(AND(LEFT(K12, 4) = LEFT(L12, 4), C12 = "Corr"), 1, "")
A13: ATL9 | B13: Flexible Thinking | C13: N | D13: 104 | E13: 99 | F13: 101 | G13: 105 | H13: 104 | I13: 105 | J13: 104 | K13: {=IF(C13="Corr", INDEX($D$1:$J$1, XMATCH(MAX(D13:J13), D13:J13)), "")} | L13: =IF(AND(LEFT(A13,3)="ATL",C13="Corr"),"htks", IF(AND(LEFT(A13,3)="LAN",C13="Corr"),"igdis", IF(AND(LEFT(A13,3)="LIT",C13="Corr"),"topel", IF(AND(LEFT(A13,3)="MAT",C13="Corr"),"rema","")))) | M13: =IF(AND(LEFT(K13, 4) = LEFT(L13, 4), C13 = "Corr"), 1, "")
... A82: MAT10 | B82: Position of Objects | C82: N | D82: 124 | E82: 118 | F82: 118 | G82: 125 | H82: 124 | I82: 125 | J82: 124 | K82: {=IF(C82="Corr", INDEX($D$1:$J$1, XMATCH(MAX(D82:J82), D82:J82)), "")} | L82: =IF(AND(LEFT(A82,3)="ATL",C82="Corr"),"htks", IF(AND(LEFT(A82,3)="LAN",C82="Corr"),"igdis", IF(AND(LEFT(A82,3)="LIT",C82="Corr"),"topel", IF(AND(LEFT(A82,3)="MAT",C82="Corr"),"rema","")))) | M82: =IF(AND(LEFT(K82, 4) = LEFT(L82, 4), C82 = "Corr"), 1, "")
L83: =IF(AND(LEFT(A83,3)="ATL",C83="Corr"),"htks", IF(AND(LEFT(A83,3)="LAN",C83="Corr"),"igdis", IF(AND(LEFT(A82,3)="LIT",C82="Corr"),"topel", IF(AND(LEFT(A83,3)="MAT",C83="Corr"),"rema","")))) | M83: =SUM(M2:M82) -> 11

Sheet Spring SPA
A1: Variable | B1: Label | C1: Type | D1: htks_score | E1: igdis_Dibujos_score | F1: igdis_Verbos_Expressivos_score | G1: rema_a_irt | H1: rema_b_irt | I1: rema_tot_irt | J1: Strongest correlation | K1: Expected | L1: Match?
A2: ATL5a | B2: Control Impulses 1 | C2: Corr | D2: 0.4298 | E2: 0.1901 | F2: 0.3642 | G2: 0.6798 | H2: 0.1652 | I2: 0.4651 | J2: {=IF(C2="Corr", INDEX($D$1:$J$1, XMATCH(MAX(D2:I2), D2:I2)), "")} -> rema_a_irt | K2: =IF(AND(LEFT(A2, 3) = "ATL", C2 = "Corr"), "htks", IF(AND(LEFT(A2, 3) = "LAN", C2 = "Corr"), "igdis", IF(AND(LEFT(A2, 3) = "MAT", C2 = "Corr"), "rema", ""))) -> htks | L2: =IF(AND(LEFT(J2, 4) = LEFT(K2, 4), C2 = "Corr"), 1, "")
A3: ATL5a | B3: Control Impulses 1 | C3: Prob | D3: 0.0966 | E3: 0.4807 | F3: 0.182 | G3: 0.0038 | H3: 0.5409 | I3: 0.0695 | J3: {=IF(C3="Corr", INDEX($D$1:$J$1, XMATCH(MAX(D3:I3), D3:I3)), "")} | K3: =IF(AND(LEFT(A3, 3) = "ATL", C3 = "Corr"), "htks", IF(AND(LEFT(A3, 3) = "LAN", C3 = "Corr"), "igdis", IF(AND(LEFT(A3, 3) = "MAT", C3 = "Corr"), "rema", ""))) | L3: =IF(AND(LEFT(J3, 4) = LEFT(K3, 4), C3 = "Corr"), 1, "")
A4: ATL5a | B4: Control Impulses 1 | C4: N | D4: 16 | E4: 16 | F4: 15 | G4: 16 | H4: 16 | I4: 16 | J4: {=IF(C4="Corr", INDEX($D$1:$J$1, XMATCH(MAX(D4:I4), D4:I4)), "")} | K4: =IF(AND(LEFT(A4, 3) = "ATL", C4 = "Corr"), "htks", IF(AND(LEFT(A4, 3) = "LAN", C4 = "Corr"), "igdis", IF(AND(LEFT(A4, 3) = "MAT", C4 = "Corr"), "rema", ""))) | L4: =IF(AND(LEFT(J4, 4) = LEFT(K4, 4), C4 = "Corr"), 1, "")
A5: ATL5b | B5: Control Impulses 2 | C5: Corr | D5: 0.4145 | E5: 0.1655 | F5: 0.0785 | G5: 0.4202 | H5: 0.0321 | I5: 0.2047 | J5: {=IF(C5="Corr", INDEX($D$1:$J$1, XMATCH(MAX(D5:I5), D5:I5)), "")} -> rema_a_irt | K5: =IF(AND(LEFT(A5, 3) = "ATL", C5 = "Corr"), "htks", IF(AND(LEFT(A5, 3) = "LAN", C5 = "Corr"), "igdis", IF(AND(LEFT(A5, 3) = "MAT", C5 = "Corr"), "rema", ""))) -> htks | L5: =IF(AND(LEFT(J5, 4) = LEFT(K5, 4), C5 = "Corr"), 1, "")
A6: ATL5b | B6: Control Impulses 2 | C6: Prob | D6: 0.0228 | E6: 0.3737 | F6: 0.6856 | G6: 0.0208 | H6: 0.8639 | I6: 0.2779 | J6: {=IF(C6="Corr", INDEX($D$1:$J$1, XMATCH(MAX(D6:I6), D6:I6)), "")} | K6: =IF(AND(LEFT(A6, 3) = "ATL", C6 = "Corr"), "htks", IF(AND(LEFT(A6, 3) = "LAN", C6 = "Corr"), "igdis", IF(AND(LEFT(A6, 3) = "MAT", C6 = "Corr"), "rema", ""))) | L6: =IF(AND(LEFT(J6, 4) = LEFT(K6, 4), C6 = "Corr"), 1, "")
A7: ATL5b | B7: Control Impulses 2 | C7: N | D7: 30 | E7: 31 | F7: 29 | G7: 30 | H7: 31 | I7: 30 | J7: {=IF(C7="Corr", INDEX($D$1:$J$1, XMATCH(MAX(D7:I7), D7:I7)), "")} | K7: =IF(AND(LEFT(A7, 3) = "ATL", C7 = "Corr"), "htks", IF(AND(LEFT(A7, 3) = "LAN", C7 = "Corr"), "igdis", IF(AND(LEFT(A7, 3) = "MAT", C7 = "Corr"), "rema", ""))) | L7: =IF(AND(LEFT(J7, 4) = LEFT(K7, 4), C7 = "Corr"), 1, "")
A8: ATL8 | B8: Working Memory 1 | C8: Corr | D8: 0.4921 | E8: 0.372 | F8: 0.4385 | G8: 0.7755 | H8: 0.3058 | I8: 0.5975 | J8: {=IF(C8="Corr", INDEX($D$1:$J$1, XMATCH(MAX(D8:I8), D8:I8)), "")} -> rema_a_irt | K8: =IF(AND(LEFT(A8, 3) = "ATL", C8 = "Corr"), "htks", IF(AND(LEFT(A8, 3) = "LAN", C8 = "Corr"), "igdis", IF(AND(LEFT(A8, 3) = "MAT", C8 = "Corr"), "rema", ""))) -> htks | L8: =IF(AND(LEFT(J8, 4) = LEFT(K8, 4), C8 = "Corr"), 1, "")
A9: ATL8 | B9: Working Memory 1 | C9: Prob | D9: 0.0078 | E9: 0.0469 | F9: 0.0221 | G9: 0 | H9: 0.1067 | I9: 0.0008 | J9: {=IF(C9="Corr", INDEX($D$1:$J$1, XMATCH(MAX(D9:I9), D9:I9)), "")} | K9: =IF(AND(LEFT(A9, 3) = "ATL", C9 = "Corr"), "htks", IF(AND(LEFT(A9, 3) = "LAN", C9 = "Corr"), "igdis", IF(AND(LEFT(A9, 3) = "MAT", C9 = "Corr"), "rema", ""))) | L9: =IF(AND(LEFT(J9, 4) = LEFT(K9, 4), C9 = "Corr"), 1, "")
A10: ATL8 | B10: Working Memory 1 | C10: N | D10: 28 | E10: 29 | F10: 27 | G10: 28 | H10: 29 | I10: 28 | J10: {=IF(C10="Corr", INDEX($D$1:$J$1, XMATCH(MAX(D10:I10), D10:I10)), "")} | K10: =IF(AND(LEFT(A10, 3) = "ATL", C10 = "Corr"), "htks", IF(AND(LEFT(A10, 3) = "LAN", C10 = "Corr"), "igdis", IF(AND(LEFT(A10, 3) = "MAT", C10 = "Corr"), "rema", ""))) | L10: =IF(AND(LEFT(J10, 4) = LEFT(K10, 4), C10 = "Corr"), 1, "")
A11: ATL9 | B11: Flexible Thinking | C11: Corr | D11: 0.2771 | E11: -0.013 | F11: 0.043 | G11: 0.2915 | H11: 0.3278 | I11: 0.3511 | J11: {=IF(C11="Corr", INDEX($D$1:$J$1, XMATCH(MAX(D11:I11), D11:I11)), "")} -> rema_tot_irt | K11: =IF(AND(LEFT(A11, 3) = "ATL", C11 = "Corr"), "htks", IF(AND(LEFT(A11, 3) = "LAN", C11 = "Corr"), "igdis", IF(AND(LEFT(A11, 3) = "MAT", C11 = "Corr"), "rema", ""))) -> htks | L11: =IF(AND(LEFT(J11, 4) = LEFT(K11, 4), C11 = "Corr"), 1, "")
A12: ATL9 | B12: Flexible Thinking | C12: Prob | D12: 0.1457 | E12: 0.9455 | F12: 0.828 | G12: 0.125 | H12: 0.077 | I12: 0.0618 | J12: {=IF(C12="Corr", INDEX($D$1:$J$1, XMATCH(MAX(D12:I12), D12:I12)), "")} | K12: =IF(AND(LEFT(A12, 3) = "ATL", C12 = "Corr"), "htks", IF(AND(LEFT(A12, 3) = "LAN", C12 = "Corr"), "igdis", IF(AND(LEFT(A12, 3) = "MAT", C12 = "Corr"), "rema", ""))) | L12: =IF(AND(LEFT(J12, 4) = LEFT(K12, 4), C12 = "Corr"), 1, "")
A13: ATL9 | B13: Flexible Thinking | C13: N | D13: 29 | E13: 30 | F13: 28 | G13: 29 | H13: 30 | I13: 29 | J13: {=IF(C13="Corr", INDEX($D$1:$J$1, XMATCH(MAX(D13:I13), D13:I13)), "")} | K13: =IF(AND(LEFT(A13, 3) = "ATL", C13 = "Corr"), "htks", IF(AND(LEFT(A13, 3) = "LAN", C13 = "Corr"), "igdis", IF(AND(LEFT(A13, 3) = "MAT", C13 = "Corr"), "rema", ""))) | L13: =IF(AND(LEFT(J13, 4) = LEFT(K13, 4), C13 = "Corr"), 1, "")
... A79: MAT10 | B79: Position of Objects | C79: N | D79: 35 | E79: 36 | F79: 34 | G79: 35 | H79: 36 | I79: 35 | J79: {=IF(C79="Corr", INDEX($D$1:$J$1, XMATCH(MAX(D79:I79), D79:I79)), "")} | K79: =IF(AND(LEFT(A79, 3) = "ATL", C79 = "Corr"), "htks", IF(AND(LEFT(A79, 3) = "LAN", C79 = "Corr"), "igdis", IF(AND(LEFT(A79, 3) = "MAT", C79 = "Corr"), "rema", ""))) | L79: =IF(AND(LEFT(J79, 4) = LEFT(K79, 4), C79 = "Corr"), 1, "")
J80: {=IF(A80="Corr", INDEX($C$1:$J$1, XMATCH(MAX(A80:I80), A80:I80)), "")} | L80: =SUM(L2:L79) -> 10
J81: {=IF(A81="Corr", INDEX($C$1:$J$1, XMATCH(MAX(A81:I81), A81:I81)), "")}
J82: {=IF(A82="Corr", INDEX($C$1:$J$1, XMATCH(MAX(A82:I82), A82:I82)), "")}

Sheet Fall ENG
A1: Variable | B1: Label | C1: Type | D1: htks_score | E1: igdis_Picture_Naming_score | F1: igdis_Which_One_Doesn't_Belong_score | G1: topel_pa_stdscore | H1: rema_a_irt | I1: rema_b_irt | J1: rema_tot_irt
A2: ATL5a | B2: {=XLOOKUP(A2, Lookup!B:B, Lookup!D:D)} -> #N/A | C2: Corr | D2: 0.4081 | E2: 0.1401 | F2: 0.2728 | G2: 0.189 | H2: 0.3501 | I2: 0.249 | J2: 0.3225
A3: ATL5a | B3: {=XLOOKUP(A3, Lookup!B:B, Lookup!D:D)} -> #N/A | C3: Prob | D3: 0 | E3: 0.1336 | F3: 0.0058 | G3: 0.0348 | H3: 0.0001 | I3: 0.0055 | J3: 0.0003
A4: ATL5a | B4: {=XLOOKUP(A4, Lookup!B:B, Lookup!D:D)} -> #N/A | C4: N | D4: 126 | E4: 116 | F4: 101 | G4: 125 | H4: 125 | I4: 123 | J4: 123
A5: ATL5b | B5: {=XLOOKUP(A5, Lookup!B:B, Lookup!D:D)} -> #N/A | C5: Corr | D5: 0.3248 | E5: 0.1354 | F5: 0.2435 | G5: 0.1491 | H5: 0.3533 | I5: 0.2326 | J5: 0.3361
A6: ATL5b | B6: {=XLOOKUP(A6, Lookup!B:B, Lookup!D:D)} -> #N/A | C6: Prob | D6: 0.0016 | E6: 0.2113 | F6: 0.0393 | G6: 0.1608 | H6: 0.0006 | I6: 0.0282 | J6: 0.0014
A7: ATL5b | B7: {=XLOOKUP(A7, Lookup!B:B, Lookup!D:D)} -> #N/A | C7: N | D7: 92 | E7: 87 | F7: 72 | G7: 90 | H7: 90 | I7: 89 | J7: 88
A8: ATL8 | B8: {=XLOOKUP(A8, Lookup!B:B, Lookup!D:D)} -> #N/A | C8: Corr | D8: 0.3004 | E8: 0.3436 | F8: 0.2804 | G8: 0.1223 | H8: 0.3417 | I8: 0.0396 | J8: 0.2219
A9: ATL8 | B9: {=XLOOKUP(A9, Lookup!B:B, Lookup!D:D)} -> #N/A | C9: Prob | D9: 0.0088 | E9: 0.0033 | F9: 0.0286 | G9: 0.2992 | H9: 0.0029 | I9: 0.7431 | J9: 0.0629
A10: ATL8 | B10: {=XLOOKUP(A10, Lookup!B:B, Lookup!D:D)} -> #N/A | C10: N | D10: 75 | E10: 71 | F10: 61 | G10: 74 | H10: 74 | I10: 71 | J10: 71
A11: LAN6 | B11: {=XLOOKUP(A11, Lookup!B:B, Lookup!D:D)} -> #N/A | C11: Corr | D11: 0.2485 | E11: 0.1097 | F11: 0.2083 | G11: 0.0807 | H11: 0.1583 | I11: 0.1238 | J11: 0.1076
A12: LAN6 | B12: {=XLOOKUP(A12, Lookup!B:B, Lookup!D:D)} -> #N/A | C12: Prob | D12: 0.0157 | E12: 0.2951 | F12: 0.0709 | G12: 0.4447 | H12: 0.1296 | I12: 0.2396 | J12: 0.3099
A13: LAN6 | B13: {=XLOOKUP(A13, Lookup!B:B, Lookup!D:D)} -> #N/A | C13: N | D13: 94 | E13: 93 | F13: 76 | G13: 92 | H13: 93 | I13: 92 | J13: 91
... A82: MAT6b | B82: {=XLOOKUP(A82, Lookup!B:B, Lookup!D:D)} -> #N/A | C82: N | D82: 111 | E82: 102 | F82: 90 | G82: 110 | H82: 109 | I82: 109 | J82: 108

Sheet Fall SPA
A1: Variable | B1: Label | C1: Type | D1: htks_score | E1: igdis_Dibujos_score | F1: igdis_Verbos_Expressivos_score | G1: rema_a_irt | H1: rema_b_irt | I1: rema_tot_irt
A2: ATL5a | B2: {=XLOOKUP(A2, Lookup!B:B, Lookup!D:D)} -> #N/A | C2: Corr | D2: 0.2287 | E2: 0.4051 | F2: 0.3598 | G2: 0.5329 | H2: 0.4539 | I2: 0.4689
A3: ATL5a | B3: {=XLOOKUP(A3, Lookup!B:B, Lookup!D:D)} -> #N/A | C3: Prob | D3: 0.2005 | E3: 0.0193 | F3: 0.0468 | G3: 0.0014 | H3: 0.0091 | I3: 0.0068
A4: ATL5a | B4: {=XLOOKUP(A4, Lookup!B:B, Lookup!D:D)} -> #N/A | C4: N | D4: 33 | E4: 33 | F4: 31 | G4: 33 | H4: 32 | I4: 32
A5: ATL5b | B5: {=XLOOKUP(A5, Lookup!B:B, Lookup!D:D)} -> #N/A | C5: Corr | D5: 0.1587 | E5: 0.3969 | F5: 0.3867 | G5: 0.32 | H5: 0.152 | I5: 0.2364
A6: ATL5b | B6: {=XLOOKUP(A6, Lookup!B:B, Lookup!D:D)} -> #N/A | C6: Prob | D6: 0.4487 | E6: 0.0608 | F6: 0.0754 | G6: 0.1189 | H6: 0.4783 | I6: 0.2662
A7: ATL5b | B7: {=XLOOKUP(A7, Lookup!B:B, Lookup!D:D)} -> #N/A | C7: N | D7: 25 | E7: 23 | F7: 22 | G7: 25 | H7: 24 | I7: 24
A8: ATL8 | B8: {=XLOOKUP(A8, Lookup!B:B, Lookup!D:D)} -> #N/A | C8: Corr | D8: 0.2025 | E8: -0.0273 | F8: 0.219 | G8: 0.3797 | H8: 0.2442 | I8: 0.3563
A9: ATL8 | B9: {=XLOOKUP(A9, Lookup!B:B, Lookup!D:D)} -> #N/A | C9: Prob | D9: 0.4058 | E9: 0.9118 | F9: 0.3983 | G9: 0.1089 | H9: 0.3288 | I9: 0.1467
A10: ATL8 | B10: {=XLOOKUP(A10, Lookup!B:B, Lookup!D:D)} -> #N/A | C10: N | D10: 19 | E10: 19 | F10: 17 | G10: 19 | H10: 18 | I10: 18
A11: LAN6 | B11: {=XLOOKUP(A11, Lookup!B:B, Lookup!D:D)} -> #N/A | C11: Corr | D11: 0.3365 | E11: -0.0631 | F11: 0.3415 | G11: 0.7324 | H11: 0.4766 | I11: 0.5751
A12: LAN6 | B12: {=XLOOKUP(A12, Lookup!B:B, Lookup!D:D)} -> #N/A | C12: Prob | D12: 0.1258 | E12: 0.7857 | F12: 0.1524 | G12: 0.0001 | H12: 0.0289 | I12: 0.0064
A13: LAN6 | B13: {=XLOOKUP(A13, Lookup!B:B, Lookup!D:D)} -> #N/A | C13: N | D13: 22 | E13: 21 | F13: 19 | G13: 22 | H13: 21 | I13: 21
... A76: MAT6b | B76: {=XLOOKUP(A76, Lookup!B:B, Lookup!D:D)} -> #N/A | C76: N | D76: 34 | E76: 33 | F76: 32 | G76: 34 | H76: 33 | I76: 33
A77: LIT3b | B77: Letter Sounds | C77: Corr | D77: 0.2224 | E77: 0.2605 | F77: 0.242 | G77: 0.5379 | H77: 0.2608 | I77: 0.376
A78: LIT3b | B78: Letter Sounds | C78: Prob | D78: 0.2062 | E78: 0.1431 | F78: 0.1977 | G78: 0.001 | H78: 0.1426 | I78: 0.031
A79: LIT3b | B79: Letter Sounds | C79: N | D79: 34 | E79: 33 | F79: 30 | G79: 34 | H79: 33 | I79: 33

Sheet Lookup
A1: Full Name | B1: Domain | C1: Label/Lang | D1: Label
A2: LIT1a: Rhyme EN | B2: {=TEXTSPLIT(A2, ": ")} -> #NAME? | D2: =SUBSTITUTE(C2, " EN", "")
A3: LIT1b: Blending & Adding EN | B3: {=TEXTSPLIT(A3, ": ")} -> #NAME? | D3: =SUBSTITUTE(C3, " EN", "")
A4: LIT1c: Segmenting EN | B4: {=TEXTSPLIT(A4, ": ")} -> #NAME? | D4: =SUBSTITUTE(C4, " EN", "")
A5: LIT1d: Decoding & Encoding EN | B5: {=TEXTSPLIT(A5, ": ")} -> #NAME? | D5: =SUBSTITUTE(C5, " EN", "")
A6: LIT2: Concepts of Print EN | B6: {=TEXTSPLIT(A6, ": ")} -> #NAME? | D6: =SUBSTITUTE(C6, " EN", "")
A7: LIT3a: Letter Names EN | B7: {=TEXTSPLIT(A7, ": ")} -> #NAME? | D7: =SUBSTITUTE(C7, " EN", "")
A8: LIT3bi: Consonant Sounds EN | B8: {=TEXTSPLIT(A8, ": ")} -> #NAME? | D8: =SUBSTITUTE(C8, " EN", "")
A9: LIT3bii: Vowel Sounds EN | B9: {=TEXTSPLIT(A9, ": ")} -> #NAME? | D9: =SUBSTITUTE(C9, " EN", "")
A10: LIT4: Retell Stories EN | B10: {=TEXTSPLIT(A10, ": ")} -> #NAME? | D10: =SUBSTITUTE(C10, " EN", "")
A11: LIT5: Answer Questions EN | B11: {=TEXTSPLIT(A11, ": ")} -> #NAME? | D11: =SUBSTITUTE(C11, " EN", "")
A12: MAT2: Subitizing EN | B12: {=TEXTSPLIT(A12, ": ")} -> #NAME? | D12: =SUBSTITUTE(C12, " EN", "")
A13: MAT3: Count 1 by 1 EN | B13: {=TEXTSPLIT(A13, ": ")} -> #NAME? | D13: =SUBSTITUTE(C13, " EN", "")
... A28: ATL9: Flexible Thinking EN | B28: {=TEXTSPLIT(A28, ": ")} -> #NAME? | D28: =SUBSTITUTE(C28, " EN", "")
